<?xml version="1.0" ?>
<mujoco>
    <default>
        <joint armature="1" damping="1" limited="true"/>
        <geom condim="3" conaffinity="0" density="5.0" friction="1 0.5 0.5" margin="0.01" rgba="0.8 0.6 0.4 1"/>
    </default>
    <worldbody>
        <body name="Base" pos="0.0 0.0 0.75">
            <joint type="free" armature="0" damping="0" limited="false" margin="0.01" pos="0 0 0"/>
            <geom type="capsule" rgba="0.8 0.6 0.4 1" size="0.25 0.9790388864670969" euler="0 90 0"/>
            <camera name="track" mode="trackcom" pos="0 -3 0.3" xyaxes="1 0 0 0 0 1"/>
            <geom name="limb0" type="capsule" fromto="0 0 0 -0.7832311091736776 0.25 0.0" size="0.08"/>
            <body name="rod_0.1" pos="-0.7832311091736776 0.3522753630110649 -0.05113768150553244">
                <geom type="capsule" fromto="-0.0 -0.10227536301106488 0.05113768150553244 0.0 0.10227536301106488 -0.05113768150553244" size="0.08" name="geom_0.1"/>
                <site pos="0 0 0" quat="0.7071067811865476 -0.0 0.316227766016838 0.632455532033676" name="site_0.1"/>
                <joint type="hinge" pos="-0.0 -0.10227536301106488 0.05113768150553244" axis="0 0 1" range="-30 30" name="joint_Base=rod_0.1"/>
                <body pos="-0.0 -0.10227536301106488 0.05113768150553244" name="p0">
                    <site name="p0"/>
                </body>
                <body name="rod_1.2" pos="0.0 0.10227536301106488 -0.20835610063027557">
                    <geom type="capsule" fromto="-0.0 -0.0 0.15721841912474313 0.0 0.0 -0.15721841912474313" size="0.08" name="geom_1.2"/>
                    <site pos="0 0 0" quat="0.7071067811865476 -0.0 0.7071067811865476 0.0" name="site_1.2"/>
                    <joint type="hinge" pos="-0.0 -0.0 0.15721841912474313" axis="-1 1 0" range="30 70" name="joint_rod_0.1=rod_1.2"/>
                    <body pos="-0.0 -0.0 0.15721841912474313" name="p1">
                        <site name="p1"/>
                    </body>
                </body>
            </body>
            <geom name="limb1" type="capsule" fromto="0 0 0 -0.2610770363912258 -0.25 0.0" size="0.08"/>
            <body name="rod_9.10" pos="-0.2610770363912258 -0.3451945575243411 -0.04759727876217054">
                <geom type="capsule" fromto="-0.0 0.09519455752434108 0.04759727876217054 0.0 -0.09519455752434108 -0.04759727876217054" size="0.08" name="geom_9.10"/>
                <site pos="0 0 0" quat="0.7071067811865476 0.0 0.316227766016838 -0.632455532033676" name="site_9.10"/>
                <joint type="hinge" pos="-0.0 0.09519455752434108 0.04759727876217054" axis="0 0 1" range="-30 30" name="joint_Base=rod_9.10"/>
                <body pos="-0.0 0.09519455752434108 0.04759727876217054" name="p9">
                    <site name="p9"/>
                </body>
                <body name="rod_10.11" pos="0.0 -0.09519455752434108 -0.14443637109833465">
                    <geom type="capsule" fromto="-0.0 -0.0 0.09683909233616411 0.0 0.0 -0.09683909233616411" size="0.08" name="geom_10.11"/>
                    <site pos="0 0 0" quat="0.7071067811865476 -0.0 0.7071067811865476 0.0" name="site_10.11"/>
                    <joint type="hinge" pos="-0.0 -0.0 0.09683909233616411" axis="1 1 0" range="30 70" name="joint_rod_9.10=rod_10.11"/>
                    <body pos="-0.0 -0.0 0.09683909233616411" name="p10">
                        <site name="p10"/>
                    </body>
                </body>
            </body>
            <geom name="limb2" type="capsule" fromto="0 0 0 0.2610770363912259 0.25 0.0" size="0.08"/>
            <body name="rod_12.13" pos="0.2610770363912259 0.3660226600145407 -0.058011330007270344">
                <geom type="capsule" fromto="-0.0 -0.1160226600145407 0.058011330007270344 0.0 0.1160226600145407 -0.058011330007270344" size="0.08" name="geom_12.13"/>
                <site pos="0 0 0" quat="0.7071067811865476 -0.0 0.31622776601683794 0.632455532033676" name="site_12.13"/>
                <joint type="hinge" pos="-0.0 -0.1160226600145407 0.058011330007270344" axis="0 0 1" range="-30 30" name="joint_Base=rod_12.13"/>
                <body pos="-0.0 -0.1160226600145407 0.058011330007270344" name="p12">
                    <site name="p12"/>
                </body>
                <body name="rod_13.14" pos="0.0 0.1160226600145407 -0.1916449563325718">
                    <geom type="capsule" fromto="-0.0 -0.0 0.13363362632530146 0.0 0.0 -0.13363362632530146" size="0.08" name="geom_13.14"/>
                    <site pos="0 0 0" quat="0.7071067811865476 -0.0 0.7071067811865476 0.0" name="site_13.14"/>
                    <joint type="hinge" pos="-0.0 -0.0 0.13363362632530146" axis="-1 1 0" range="-70 -30" name="joint_rod_12.13=rod_13.14"/>
                    <body pos="-0.0 -0.0 0.13363362632530146" name="p13">
                        <site name="p13"/>
                    </body>
                </body>
            </body>
        </body>
    </worldbody>
    <actuator>
        <motor gear="150" ctrlrange="-1.0 1.0" ctrllimited="true" joint="joint_Base=rod_0.1"/>
        <motor gear="150" ctrlrange="-1.0 1.0" ctrllimited="true" joint="joint_rod_0.1=rod_1.2"/>
        <motor gear="150" ctrlrange="-1.0 1.0" ctrllimited="true" joint="joint_Base=rod_9.10"/>
        <motor gear="150" ctrlrange="-1.0 1.0" ctrllimited="true" joint="joint_rod_9.10=rod_10.11"/>
        <motor gear="150" ctrlrange="-1.0 1.0" ctrllimited="true" joint="joint_Base=rod_12.13"/>
        <motor gear="150" ctrlrange="-1.0 1.0" ctrllimited="true" joint="joint_rod_12.13=rod_13.14"/>
    </actuator>
    <sensor>
        <accelerometer site="site_0.1"/>
        <gyro site="site_0.1"/>
        <magnetometer site="site_0.1"/>
        <accelerometer site="site_1.2"/>
        <gyro site="site_1.2"/>
        <magnetometer site="site_1.2"/>
        <accelerometer site="site_9.10"/>
        <gyro site="site_9.10"/>
        <magnetometer site="site_9.10"/>
        <accelerometer site="site_10.11"/>
        <gyro site="site_10.11"/>
        <magnetometer site="site_10.11"/>
        <accelerometer site="site_12.13"/>
        <gyro site="site_12.13"/>
        <magnetometer site="site_12.13"/>
        <accelerometer site="site_13.14"/>
        <gyro site="site_13.14"/>
        <magnetometer site="site_13.14"/>
    </sensor>
    <contact>
        <pair geom1="geom_0.1" geom2="floor"/>
        <pair geom1="geom_1.2" geom2="floor"/>
        <pair geom1="geom_9.10" geom2="floor"/>
        <pair geom1="geom_10.11" geom2="floor"/>
        <pair geom1="geom_12.13" geom2="floor"/>
        <pair geom1="geom_13.14" geom2="floor"/>
    </contact>
</mujoco>
